Workbook

Sheet Read me
A1: Mail OPS content map: what has to be written and built
A2: Maps every topic of the 15-day curriculum to its LMS item, Quip articles and Training Kit items. Counts below are formulas over the other sheets and update as you change statuses.
A4: Quip articles by type and week first needed
A5: Article type | B5: Week 1 | C5: Week 2 | D5: Week 3
A6: Hub | B6: =COUNTIFS('Quip articles'!$C$5:$C$63,$A6,'Quip articles'!$F$5:$F$63,1) -> 7 | C6: =COUNTIFS('Quip articles'!$C$5:$C$63,$A6,'Quip articles'!$F$5:$F$63,2) -> 0 | D6: =COUNTIFS('Quip articles'!$C$5:$C$63,$A6,'Quip articles'!$F$5:$F$63,3) -> 0
A7: Concept | B7: =COUNTIFS('Quip articles'!$C$5:$C$63,$A7,'Quip articles'!$F$5:$F$63,1) -> 9 | C7: =COUNTIFS('Quip articles'!$C$5:$C$63,$A7,'Quip articles'!$F$5:$F$63,2) -> 5 | D7: =COUNTIFS('Quip articles'!$C$5:$C$63,$A7,'Quip articles'!$F$5:$F$63,3) -> 0
A8: Workflow / SOP | B8: =COUNTIFS('Quip articles'!$C$5:$C$63,$A8,'Quip articles'!$F$5:$F$63,1) -> 6 | C8: =COUNTIFS('Quip articles'!$C$5:$C$63,$A8,'Quip articles'!$F$5:$F$63,2) -> 6 | D8: =COUNTIFS('Quip articles'!$C$5:$C$63,$A8,'Quip articles'!$F$5:$F$63,3) -> 3
A9: Tool Guide | B9: =COUNTIFS('Quip articles'!$C$5:$C$63,$A9,'Quip articles'!$F$5:$F$63,1) -> 10 | C9: =COUNTIFS('Quip articles'!$C$5:$C$63,$A9,'Quip articles'!$F$5:$F$63,2) -> 0 | D9: =COUNTIFS('Quip articles'!$C$5:$C$63,$A9,'Quip articles'!$F$5:$F$63,3) -> 0
A10: Decision Guide | B10: =COUNTIFS('Quip articles'!$C$5:$C$63,$A10,'Quip articles'!$F$5:$F$63,1) -> 1 | C10: =COUNTIFS('Quip articles'!$C$5:$C$63,$A10,'Quip articles'!$F$5:$F$63,2) -> 3 | D10: =COUNTIFS('Quip articles'!$C$5:$C$63,$A10,'Quip articles'!$F$5:$F$63,3) -> 1
A11: Reference | B11: =COUNTIFS('Quip articles'!$C$5:$C$63,$A11,'Quip articles'!$F$5:$F$63,1) -> 4 | C11: =COUNTIFS('Quip articles'!$C$5:$C$63,$A11,'Quip articles'!$F$5:$F$63,2) -> 1 | D11: =COUNTIFS('Quip articles'!$C$5:$C$63,$A11,'Quip articles'!$F$5:$F$63,3) -> 1
A12: Change Log | B12: =COUNTIFS('Quip articles'!$C$5:$C$63,$A12,'Quip articles'!$F$5:$F$63,1) -> 2 | C12: =COUNTIFS('Quip articles'!$C$5:$C$63,$A12,'Quip articles'!$F$5:$F$63,2) -> 0 | D12: =COUNTIFS('Quip articles'!$C$5:$C$63,$A12,'Quip articles'!$F$5:$F$63,3) -> 0
A13: Total | B13: =SUM(B6:B12) -> 39 | C13: =SUM(C6:C12) -> 15 | D13: =SUM(D6:D12) -> 5
A15: Writing progress
A16: Status | B16: Quip articles | C16: LMS items | D16: Training Kit
A17: Not started | B17: =COUNTIF('Quip articles'!$O$5:$O$63,$A17) -> 59 | C17: =COUNTIF('LMS items'!$J$5:$J$33,$A17) -> 29 | D17: =COUNTIF('Training Kit'!$H$5:$H$59,$A17) -> 55
A18: Drafting | B18: =COUNTIF('Quip articles'!$O$5:$O$63,$A18) -> 0 | C18: =COUNTIF('LMS items'!$J$5:$J$33,$A18) -> 0 | D18: =COUNTIF('Training Kit'!$H$5:$H$59,$A18) -> 0
A19: Storyboarding | B19: =COUNTIF('Quip articles'!$O$5:$O$63,$A19) -> 0 | C19: =COUNTIF('LMS items'!$J$5:$J$33,$A19) -> 0 | D19: =COUNTIF('Training Kit'!$H$5:$H$59,$A19) -> 0
A20: In review | B20: =COUNTIF('Quip articles'!$O$5:$O$63,$A20) -> 0 | C20: =COUNTIF('LMS items'!$J$5:$J$33,$A20) -> 0 | D20: =COUNTIF('Training Kit'!$H$5:$H$59,$A20) -> 0
A21: Approved | B21: =COUNTIF('Quip articles'!$O$5:$O$63,$A21) -> 0 | C21: =COUNTIF('LMS items'!$J$5:$J$33,$A21) -> 0 | D21: =COUNTIF('Training Kit'!$H$5:$H$59,$A21) -> 0
A22: Built | B22: =COUNTIF('Quip articles'!$O$5:$O$63,$A22) -> 0 | C22: =COUNTIF('LMS items'!$J$5:$J$33,$A22) -> 0 | D22: =COUNTIF('Training Kit'!$H$5:$H$59,$A22) -> 0
A23: Published | B23: =COUNTIF('Quip articles'!$O$5:$O$63,$A23) -> 0 | C23: =COUNTIF('LMS items'!$J$5:$J$33,$A23) -> 0 | D23: =COUNTIF('Training Kit'!$H$5:$H$59,$A23) -> 0
A24: Total | B24: =SUM(B17:B23) -> 59 | C24: =SUM(C17:C23) -> 29 | D24: =SUM(D17:D23) -> 55
A26: LMS and Training Kit items by type
A27: Item type | B27: Count
A28: Module | B28: =COUNTIF('LMS items'!$C$5:$C$33,$A28) -> 22
A29: Check-only module | B29: =COUNTIF('LMS items'!$C$5:$C$33,$A29) -> 4
A30: Assessment | B30: =COUNTIF('LMS items'!$C$5:$C$33,$A30) -> 3
A31: Total | B31: =SUM(B28:B30) -> 29
A32: Trainer Guide | B32: =COUNTIF('Training Kit'!$C$5:$C$59,$A32) -> 39
A33: Hands-on Activity | B33: =COUNTIF('Training Kit'!$C$5:$C$59,$A33) -> 16
A34: Total | B34: =SUM(B32:B33) -> 55
A36: How to use this workbook
A37: Curriculum map | B37: Start here to see what each curriculum row becomes. Edit only if the curriculum changes.
A38: Quip articles | B38: The writing backlog, in the order articles are first needed. Fill in the yellow columns: legacy triage result, legacy link, owner, writer, status.
A39: LMS items | B39: Every module, check-only module and assessment, with the articles it links to. Adjust planned questions and status in the yellow columns.
A40: Training Kit | B40: Trainer Guides and Hands-on Activities for the restricted folder. Fill in owner and status.
A41: Yellow cells | B41: Inputs for you to fill in. Everything else is the plan, or a formula.
A43: Decisions, gaps and assumptions
A44: Scope | B44: Every topic row of the 15-day curriculum is mapped. Daily recaps and wrap-ups are not listed row by row; one Trainer Guide (TG-GEN-recap-wrap) covers how to run them.
A45: LMS modules | B45: SPL and Blended rows each become one LMS module (M-Wn-nn), numbered in curriculum order within each week.
...

Sheet Curriculum map
A1: Content map: 15-day curriculum to LMS, Quip and Training Kit
A2: One row per curriculum topic. Daily recaps and wrap-ups are run from TG-GEN-recap-wrap and are not listed. IDs follow the guidelines pack; see Read me for decisions to confirm.
A4: Day | B4: Week | C4: Curriculum topic | D4: Modality | E4: Mins | F4: LMS item | G4: LMS item type | H4: Quip articles | I4: Trainer Guide | J4: Hands-on Activity | K4: Content readiness
A5: 1 | B5: 1 | C5: Team Mission & Objectives - Mail OPS | D5: SPL | E5: 75 | F5: M-W1-01 | G5: Module | H5: KA-FND-001 | K5: Partly ready – SME to add
A6: 1 | B6: 1 | C6: Privacy principles and data handling boundaries | D6: SPL | E6: 45 | F6: M-W1-02 | G6: Module | H6: KA-FND-002 | K6: Partly ready – SME to add
A7: 1 | B7: 1 | C7: iCloud and iCloud Mail | D7: SPL | E7: 75 | F7: M-W1-03 | G7: Module | H7: KA-FND-003 | K7: Ready – Module 1 guide
A8: 1 | B8: 1 | C8: iCloud+ mail features | D8: SPL | E8: 60 | F8: M-W1-04 | G8: Module | H8: KA-FND-004 | K8: Ready – Module 1 guide
A9: 1 | B9: 1 | C9: Hands on: iCloud and iCloud+ Mail | D9: Activity | E9: 120 | F9: None | G9: Attendance only | H9: KA-FND-003, KA-FND-004 | I9: TG-D01-icloud-handson | J9: HA-FND-001 | K9: Ops to arrange
A10: 2 | B10: 1 | C10: Mail flow architecture | D10: Blended | E10: 90 | F10: M-W1-05 | G10: Module | H10: KA-FND-005 | I10: TG-M-W1-05 | K10: Ready – Module 1 guide
A11: 2 | B11: 1 | C11: Tool Overview: Heimdall | D11: SPL | E11: 60 | F11: M-W1-06 | G11: Module | H11: KA-TOOL-002, KA-FND-006, KA-OUT-020, KA-OUT-021 | K11: Partly ready – SME to add
A12: 2 | B12: 1 | C12: Tool Walkthrough: Heimdall | D12: ILT | E12: 60 | F12: None | G12: Attendance only | H12: KA-TOOL-002, KA-OUT-020, KA-OUT-022 | I12: TG-D02-heimdall-walkthrough | J12: HA-TOOL-002 | K12: SME to provide
A13: 2 | B13: 1 | C13: URL/SUPs | D13: ILT | E13: 60 | F13: M-W1-07 | G13: Check-only module | H13: KA-IN-001 | I13: TG-D02-url-sups | K13: SME to provide
A14: 2 | B14: 1 | C14: Hands on: URL/SUPs | D14: Activity | E14: 60 | F14: None | G14: Attendance only | H14: KA-IN-001 | I14: TG-D02-url-sups | J14: HA-IN-001 | K14: SME to provide
A15: 3 | B15: 1 | C15: Tools overview - part 1 (Splunk) - Investigate | D15: Blended | E15: 90 | F15: M-W1-08 | G15: Module | H15: KA-TOOL-003, KA-TOOL-004 | I15: TG-M-W1-08 | K15: SME to provide
A16: 3 | B16: 1 | C16: Hands on: Splunk | D16: Activity | E16: 30 | F16: None | G16: Attendance only | H16: KA-TOOL-004 | I16: TG-M-W1-08 | J16: HA-TOOL-001 | K16: SME to provide
A17: 3 | B17: 1 | C17: Tools overview - part 1 (Sonar) - Investigate | D17: SPL | E17: 60 | F17: M-W1-09 | G17: Module | H17: KA-TOOL-005, KA-GEN-006 | K17: Partly ready – SME to add
A18: 3 | B18: 1 | C18: Hands on: Sonar | D18: Activity | E18: 60 | F18: None | G18: Attendance only | H18: KA-TOOL-005, KA-GEN-006 | I18: TG-D03-sonar-handson | J18: HA-TOOL-003 | K18: Ops to arrange
A19: 3 | B19: 1 | C19: Tools overview - part 2 (Proofpoint, Bazooka, Gattler) - Mitigate | D19: Blended | E19: 90 | F19: M-W1-10 | G19: Module | H19: KA-TOOL-006, KA-TOOL-007, KA-TOOL-008 | I19: TG-M-W1-10 | K19: Partly ready – SME to add
A20: 4 | B20: 1 | C20: Tools overview - part 3 (Radar, Slack, Quip) - Engineer | D20: SPL | E20: 45 | F20: M-W1-11 | G20: Module | H20: KA-TOOL-009, KA-TOOL-010 | K20: Partly ready – SME to add
A21: 4 | B21: 1 | C21: Tools overview - part 4 (Khiron, iHawk) - Other tools | D21: SPL | E21: 45 | F21: M-W1-12 | G21: Module | H21: KA-TOOL-011, KA-TOOL-012 | K21: SME to provide
A22: 4 | B22: 1 | C22: Hands on: Tools by stage | D22: Activity | E22: 60 | F22: None | G22: Attendance only | H22: KA-TOOL-001 | I22: TG-D04-tools-by-stage | J22: HA-TOOL-004 | K22: Trainer to build
A23: 4 | B23: 1 | C23: The 14-stage milter chain | D23: Blended | E23: 90 | F23: M-W1-13 | G23: Module | H23: KA-FND-007 | I23: TG-M-W1-13 | K23: Ready – Module 1 guide
A24: 4 | B24: 1 | C24: Hands on: Header analysis with samples | D24: Activity | E24: 90 | F24: None | G24: Attendance only | H24: KA-FND-008, KA-FND-007 | I24: TG-D04-header-analysis | J24: HA-FND-002 | K24: SME to provide
A25: 5 | B25: 1 | C25: Inbound Mail Flow: Deep Dive | D25: Blended | E25: 90 | F25: M-W1-14 | G25: Module | H25: KA-FND-009 | I25: TG-M-W1-14 | K25: Ready – Module 1 guide
A26: 5 | B26: 1 | C26: Hands on: Inbound mail tracing | D26: Activity | E26: 75 | F26: None | G26: Attendance only | H26: KA-IN-002 | I26: TG-D05-inbound-tracing | J26: HA-IN-002 | K26: SME to provide
A27: 5 | B27: 1 | C27: Outbound Mail Flow: Deep Dive | D27: Blended | E27: 90 | F27: M-W1-15 | G27: Module | H27: KA-FND-010 | I27: TG-M-W1-15 | K27: Ready – Module 1 guide
A28: 5 | B28: 1 | C28: Hands on: Outbound mail tracing | D28: Activity | E28: 75 | F28: None | G28: Attendance only | H28: KA-OUT-001 | I28: TG-D05-outbound-tracing | J28: HA-OUT-001 | K28: SME to provide
A29: 6 | B29: 2 | C29: Week 1 Knowledge Check | D29: Assessment | E29: 60 | F29: A-D06 | G29: Assessment | I29: TG-D06-knowledge-check | K29: Trainer to build
A30: 6 | B30: 2 | C30: Knowledge Check Review | D30: Activity | E30: 45 | F30: None | G30: Attendance only | I30: TG-D06-knowledge-check | K30: Trainer to build
A31: 6 | B31: 2 | C31: Our operating model: Identify, Mitigate, Engineer | D31: Blended | E31: 90 | F31: M-W2-01 | G31: Module | H31: KA-FND-011 | I31: TG-M-W2-01 | K31: Ready – Module 1 guide
A32: 6 | B32: 2 | C32: Abuse landscape | D32: SPL | E32: 60 | F32: M-W2-02 | G32: Module | H32: KA-FND-012 | K32: Ready – Module 1 guide
A33: 6 | B33: 2 | C33: Abuse landscape in iCloud Outbound | D33: ILT | E33: 120 | F33: M-W2-03 | G33: Check-only module | H33: KA-OUT-002, KA-OUT-003 | I33: TG-D06-outbound-abuse | K33: SME to provide
A34: 7 | B34: 2 | C34: Types/Actions on accounts | D34: ILT | E34: 90 | F34: M-W2-04 | G34: Check-only module | H34: KA-OUT-010, KA-OUT-011 | I34: TG-D07-account-actions | K34: SME to provide
A35: 7 | B35: 2 | C35: Actioning a case | D35: Blended | E35: 90 | F35: M-W2-05 | G35: Module | H35: KA-GEN-005, KA-GEN-006, KA-FND-013 | I35: TG-M-W2-05 | K35: Partly ready – SME to add
A36: 7 | B36: 2 | C36: Hands-on with sample accounts | D36: Activity | E36: 150 | F36: None | G36: Attendance only | H36: KA-OUT-010, KA-OUT-011, KA-OUT-012 | I36: TG-D07-sample-accounts | J36: HA-OUT-002 | K36: SME to provide
A37: 8 | B37: 2 | C37: Hands-on with sample accounts | D37: Activity | E37: 270 | F37: None | G37: Attendance only | H37: KA-OUT-010, KA-OUT-011, KA-OUT-012 | I37: TG-D08-sample-accounts | J37: HA-OUT-003 | K37: SME to provide
A38: 8 | B38: 2 | C38: Trainer case review | D38: ILT | E38: 60 | F38: None | G38: Attendance only | I38: TG-D08-case-review | K38: Trainer to build
A39: 9 | B39: 2 | C39: Working with Postmaster | D39: Blended | E39: 90 | F39: M-W2-06 | G39: Module | H39: KA-PM-001, KA-PM-002, KA-PM-003, KA-PM-004 | I39: TG-M-W2-06 | K39: Partly ready – SME to add
A40: 9 | B40: 2 | C40: Hands on: Postmaster cases | D40: Activity | E40: 90 | F40: None | G40: Attendance only | H40: KA-PM-002, KA-PM-003, KA-PM-004 | I40: TG-D09-postmaster-handson | J40: HA-PM-001 | K40: SME to provide
A41: 9 | B41: 2 | C41: Other Ops workflow - Spike in user spam reports | D41: Blended | E41: 60 | F41: M-W2-07 | G41: Module | H41: KA-PB-001 | I41: TG-M-W2-07 | K41: Ready – Module 1 guide
...

Sheet Quip articles
A1: Quip article inventory and writing backlog
A2: Sorted by the day each article is first needed, so it doubles as the writing order. Yellow columns are yours to fill in.
A4: KA ID | B4: Title | C4: Type | D4: Folder | E4: First needed (day) | F4: Week | G4: Used in (curriculum rows) | H4: Times used | I4: Linked LMS items | J4: Source material | K4: New or legacy | L4: Legacy link | M4: Owner (SME / Ops) | N4: Writer | O4: Status
A5: KA-FND-000 | B5: Foundations hub | C5: Hub | D5: 01 Foundations | E5: 1 | F5: 1 | G5: Before launch (navigation and setup) | H5: 0 | I5: None | J5: Trainer to build | K5: To triage | O5: Not started
A6: KA-FND-001 | B6: Mail OPS mission, team and roles | C6: Concept | D6: 01 Foundations | E6: 1 | F6: 1 | G6: D1: Team Mission & Objectives - Mail OPS | H6: 1 | I6: M-W1-01, A-D06, A-D15 | J6: Guide §1 + SME (Apple ecosystem, T&S intro) | K6: To triage | O6: Not started
A7: KA-FND-002 | B7: Privacy principles and data handling | C7: Concept | D7: 01 Foundations | E7: 1 | F7: 1 | G7: D1: Privacy principles and data handling boundaries | H7: 1 | I7: M-W1-02, A-D06, A-D15 | J7: Guide §1, §15 + SME (GDPR, incidents) | K7: To triage | O7: Not started
A8: KA-FND-003 | B8: Apple Account, iCloud and iCloud Mail | C8: Concept | D8: 01 Foundations | E8: 1 | F8: 1 | G8: D1: iCloud and iCloud Mail D1: Hands on: iCloud and iCloud+ Mail | H8: 2 | I8: M-W1-03, A-D06, A-D15 | J8: Guide §2, §3, §11 | K8: To triage | O8: Not started
A9: KA-FND-004 | B9: iCloud+ mail features | C9: Concept | D9: 01 Foundations | E9: 1 | F9: 1 | G9: D1: iCloud+ mail features D1: Hands on: iCloud and iCloud+ Mail | H9: 2 | I9: M-W1-04, A-D06, A-D15 | J9: Guide §2, §8 | K9: To triage | O9: Not started
A10: KA-GEN-001 | B10: Mail OPS home hub | C10: Hub | D10: 00 Start Here | E10: 1 | F10: 1 | G10: D15: Transition to process | H10: 1 | I10: None | J10: Trainer to build | K10: To triage | O10: Not started
A11: KA-GEN-002 | B11: Mail OPS Glossary | C11: Reference | D11: 00 Start Here | E11: 1 | F11: 1 | G11: Before launch (navigation and setup) | H11: 0 | I11: None | J11: Module 1 guide §14 Ops terms | K11: To triage | O11: Not started
A12: KA-GEN-003 | B12: What's New | C12: Change Log | D12: 00 Start Here | E12: 1 | F12: 1 | G12: Before launch (navigation and setup) | H12: 0 | I12: None | J12: Set up once | K12: To triage | O12: Not started
A13: KA-GEN-004 | B13: What's New Archive | C13: Change Log | D13: 99 Archive | E13: 1 | F13: 1 | G13: Before launch (navigation and setup) | H13: 0 | I13: None | J13: Set up once | K13: To triage | O13: Not started
A14: KA-IN-000 | B14: Inbound hub | C14: Hub | D14: 03 Inbound | E14: 1 | F14: 1 | G14: Before launch (navigation and setup) | H14: 0 | I14: None | J14: Trainer to build | K14: To triage | O14: Not started
A15: KA-OUT-000 | B15: Outbound hub | C15: Hub | D15: 04 Outbound | E15: 1 | F15: 1 | G15: Before launch (navigation and setup) | H15: 0 | I15: None | J15: Trainer to build | K15: To triage | O15: Not started
A16: KA-PB-000 | B16: Playbooks hub | C16: Hub | D16: 06 Playbooks | E16: 1 | F16: 1 | G16: Before launch (navigation and setup) | H16: 0 | I16: None | J16: Trainer to build | K16: To triage | O16: Not started
... A63: KA-GEN-008 | B63: Escalation contacts | C63: Reference | D63: 00 Start Here | E63: 14 | F63: 3 | G63: D14: Guardrails and escalation refresher | H63: 1 | I63: M-W3-03, A-D15 | J63: SME / Ops | K63: To triage | O63: Not started

Sheet LMS items
A1: LMS modules and assessments
A2: Planned questions are suggested starting points (4 per module or check, 20 for A-D06, 15 scenarios for A-D10, 30 for A-D15); adjust them in the yellow column.
A4: LMS ID | B4: Title | C4: Type | D4: Week | E4: Day | F4: Curriculum row(s) | G4: Linked Quip articles | H4: Trainer Guide | I4: Planned questions | J4: Status
A5: M-W1-01 | B5: Team Mission & Objectives - Mail OPS | C5: Module | D5: 1 | E5: 1 | F5: Team Mission & Objectives - Mail OPS | G5: KA-FND-001 | H5: None | I5: 4 | J5: Not started
A6: M-W1-02 | B6: Privacy principles and data handling boundaries | C6: Module | D6: 1 | E6: 1 | F6: Privacy principles and data handling boundaries | G6: KA-FND-002 | H6: None | I6: 4 | J6: Not started
A7: M-W1-03 | B7: iCloud and iCloud Mail | C7: Module | D7: 1 | E7: 1 | F7: iCloud and iCloud Mail | G7: KA-FND-003 | H7: None | I7: 4 | J7: Not started
A8: M-W1-04 | B8: iCloud+ mail features | C8: Module | D8: 1 | E8: 1 | F8: iCloud+ mail features | G8: KA-FND-004 | H8: None | I8: 4 | J8: Not started
A9: M-W1-05 | B9: Mail flow architecture | C9: Module | D9: 1 | E9: 2 | F9: Mail flow architecture | G9: KA-FND-005 | H9: TG-M-W1-05 | I9: 4 | J9: Not started
A10: M-W1-06 | B10: Tool Overview: Heimdall | C10: Module | D10: 1 | E10: 2 | F10: Tool Overview: Heimdall | G10: KA-TOOL-002, KA-FND-006, KA-OUT-020, KA-OUT-021 | H10: None | I10: 4 | J10: Not started
A11: M-W1-07 | B11: URL/SUPs | C11: Check-only module | D11: 1 | E11: 2 | F11: URL/SUPs | G11: KA-IN-001 | H11: TG-D02-url-sups | I11: 4 | J11: Not started
A12: M-W1-08 | B12: Tools overview - part 1 (Splunk) - Investigate | C12: Module | D12: 1 | E12: 3 | F12: Tools overview - part 1 (Splunk) - Investigate | G12: KA-TOOL-003, KA-TOOL-004 | H12: TG-M-W1-08 | I12: 4 | J12: Not started
A13: M-W1-09 | B13: Tools overview - part 1 (Sonar) - Investigate | C13: Module | D13: 1 | E13: 3 | F13: Tools overview - part 1 (Sonar) - Investigate | G13: KA-TOOL-005, KA-GEN-006 | H13: None | I13: 4 | J13: Not started
A14: M-W1-10 | B14: Tools overview - part 2 (Proofpoint, Bazooka, Gattler) - Mitigate | C14: Module | D14: 1 | E14: 3 | F14: Tools overview - part 2 (Proofpoint, Bazooka, Gattler) - Mitigate | G14: KA-TOOL-006, KA-TOOL-007, KA-TOOL-008 | H14: TG-M-W1-10 | I14: 4 | J14: Not started
A15: M-W1-11 | B15: Tools overview - part 3 (Radar, Slack, Quip) - Engineer | C15: Module | D15: 1 | E15: 4 | F15: Tools overview - part 3 (Radar, Slack, Quip) - Engineer | G15: KA-TOOL-009, KA-TOOL-010 | H15: None | I15: 4 | J15: Not started
A16: M-W1-12 | B16: Tools overview - part 4 (Khiron, iHawk) - Other tools | C16: Module | D16: 1 | E16: 4 | F16: Tools overview - part 4 (Khiron, iHawk) - Other tools | G16: KA-TOOL-011, KA-TOOL-012 | H16: None | I16: 4 | J16: Not started
... A33: A-D15 | B33: Final Certification (theory and practical) | C33: Assessment | D33: 3 | E33: 15 | F33: Final Certification - Theory; Final Certification - Practical | G33: KA-FND-001, KA-FND-002, KA-FND-003, KA-FND-004, KA-FND-005, KA-FND-006, KA-FND-007, KA-FND-008, KA-FND-009, KA-FND-010, KA-FND-011, KA-FND-012, KA-FND-013, KA-GEN-005, KA-GEN-006, KA-GEN-007, KA-GEN-008, KA-IN-001, KA-IN-002, KA-OUT-001, KA-OUT-002, KA-OUT-003, KA-OUT-010, KA-OUT-011, KA-OUT-012, KA-OUT-020, KA-OUT-021, KA-OUT-022, KA-OUT-023, KA-OUT-024, KA-PB-001, KA-PB-002, KA-PB-003, KA-PM-001, KA-PM-002, KA-PM-003, KA-PM-004, KA-TOOL-001, KA-TOOL-002, KA-TOOL-003, KA-TOOL-004, KA-TOOL-005, KA-TOOL-006, KA-TOOL-007, KA-TOOL-008, KA-TOOL-009, KA-TOOL-010, KA-TOOL-011, KA-TOOL-012 | H33: TG-D15-certification | I33: 30 | J33: Not started
H34: Total questions | I34: =SUM(I5:I33) -> 169

Sheet Training Kit
A1: Training Kit items (restricted folder 90 Training Kit)
A2: Trainer Guides and Hands-on Activities. Activities rely on SME sample data listed in the curriculum workbook's SME inputs sheet.
A4: ID | B4: Title | C4: Type | D4: First used (day) | E4: Curriculum row(s) | F4: Quip articles it points to | G4: Owner | H4: Status
A5: TG-D01-icloud-handson | B5: Trainer Guide: Hands on: iCloud and iCloud+ Mail | C5: Trainer Guide | D5: 1 | E5: Hands on: iCloud and iCloud+ Mail | F5: KA-FND-003, KA-FND-004 | H5: Not started
A6: TG-GEN-recap-wrap | B6: Trainer Guide: Daily recap and wrap-up | C6: Trainer Guide | D6: 1 | E6: Day n Recap Quick Wrap-Up | F6: None | H6: Not started
A7: HA-FND-001 | B7: iCloud and iCloud+ Mail hands-on | C7: Hands-on Activity | D7: 1 | E7: Hands on: iCloud and iCloud+ Mail | F7: KA-FND-003, KA-FND-004 | H7: Not started
A8: TG-D02-heimdall-walkthrough | B8: Trainer Guide: Tool Walkthrough: Heimdall | C8: Trainer Guide | D8: 2 | E8: Tool Walkthrough: Heimdall | F8: KA-TOOL-002, KA-OUT-020, KA-OUT-022 | H8: Not started
A9: TG-D02-url-sups | B9: Trainer Guide: URL/SUPs | C9: Trainer Guide | D9: 2 | E9: URL/SUPs Hands on: URL/SUPs | F9: KA-IN-001 | H9: Not started
A10: TG-M-W1-05 | B10: Trainer Guide: Mail flow architecture | C10: Trainer Guide | D10: 2 | E10: Mail flow architecture | F10: KA-FND-005 | H10: Not started
A11: HA-IN-001 | B11: URL/SUP practice requests | C11: Hands-on Activity | D11: 2 | E11: Hands on: URL/SUPs | F11: KA-IN-001 | H11: Not started
A12: HA-TOOL-002 | B12: Write and read back a Heimdall rule | C12: Hands-on Activity | D12: 2 | E12: Tool Walkthrough: Heimdall | F12: KA-TOOL-002, KA-OUT-020, KA-OUT-022 | H12: Not started
A13: TG-D03-sonar-handson | B13: Trainer Guide: Hands on: Sonar | C13: Trainer Guide | D13: 3 | E13: Hands on: Sonar | F13: KA-TOOL-005, KA-GEN-006 | H13: Not started
A14: TG-M-W1-08 | B14: Trainer Guide: Tools overview - part 1 (Splunk) - Investigate | C14: Trainer Guide | D14: 3 | E14: Tools overview - part 1 (Splunk) - Investigate Hands on: Splunk | F14: KA-TOOL-003, KA-TOOL-004 | H14: Not started
A15: TG-M-W1-10 | B15: Trainer Guide: Tools overview - part 2 (Proofpoint, Bazooka, Gattler) - Mitigate | C15: Trainer Guide | D15: 3 | E15: Tools overview - part 2 (Proofpoint, Bazooka, Gattler) - Mitigate | F15: KA-TOOL-006, KA-TOOL-007, KA-TOOL-008 | H15: Not started
A16: HA-TOOL-001 | B16: Splunk indexes and queries round robin | C16: Hands-on Activity | D16: 3 | E16: Hands on: Splunk | F16: KA-TOOL-004 | H16: Not started
... A59: TG-D15-transition | B59: Trainer Guide: Transition to process | C59: Trainer Guide | D59: 15 | E59: Transition to process | F59: KA-GEN-001 | H59: Not started
